<?xml version="1.0" ?>
<sdf version="1.5">
  <model name="rover">
    <static>false</static>
    <link name="base_link">
      <inertial>
        <!-- subtracted wheel weights from dry weight of 771 kg -->
        <!-- http://www.polaris.com/en-us/ranger-utv/side-by-sides/ranger-ev/specifications -->
        <mass>720.0</mass>
        <inertia>
          <ixx>140</ixx>
          <ixy>0.0</ixy>
          <iyy>550</iyy>
          <ixz>0.0</ixz>
          <iyz>0.0</iyz>
          <izz>550</izz>
        </inertia>
        <!-- chassis c.o.g. near lateral/longitudinal center, height of 0.4 m -->
        <pose>0 0 0.335 0 0 0</pose>
      </inertial>
      <visual name="visual">
        <pose>0 0 0.3 1.570796 0 -1.570796</pose>
        <geometry>
          <mesh>
            <uri>model://kart/meshes/chassis.obj</uri>
          </mesh>
        </geometry>
      </visual>
      <collision name="base_link_bottom">
        <pose>0 0.0 0.335 0 0 0</pose>
        <geometry>
          <box>
            <size>1.0 0.5 0.06</size>
          </box>
        </geometry>
      </collision>
    </link>
    <link name='rover/imu_link'>
      <pose>0 0 0 0 0 0</pose>
      <inertial>
        <pose>0 0 0 0 0 0</pose>
        <mass>0.015</mass>
        <inertia>
          <ixx>1e-05</ixx>
          <ixy>0</ixy>
          <ixz>0</ixz>
          <iyy>1e-05</iyy>
          <iyz>0</iyz>
          <izz>1e-05</izz>
        </inertia>
      </inertial>
    </link>
    <joint name='rover/imu_joint' type='revolute'>
      <child>rover/imu_link</child>
      <parent>base_link</parent>
      <axis>
        <xyz>1 0 0</xyz>
        <limit>
          <lower>0</lower>
          <upper>0</upper>
          <effort>0</effort>
          <velocity>0</velocity>
        </limit>
        <dynamics>
          <spring_reference>0</spring_reference>
          <spring_stiffness>0</spring_stiffness>
        </dynamics>
        <use_parent_model_frame>1</use_parent_model_frame>
      </axis>
    </joint>
    <link name="front_left_wheel">
      <pose>0.47 0.5 0.34697 -1.52 0.0 0.0</pose>
      <inertial>
        <mass>12</mass>
        <!-- estimated from http://www.rzrforums.net/wheels-tires/1729-tire-wheel-weights-most-sizes.html -->
        <inertia>
          <ixx>0.5</ixx>
          <ixy>0.0</ixy>
          <iyy>0.5</iyy>
          <ixz>0.0</ixz>
          <iyz>0.0</iyz>
          <izz>1.0</izz>
        </inertia>
      </inertial>
      <collision name="collision">
        <geometry>
          <cylinder>
            <radius>0.127</radius>
            <length>0.1143</length>
          </cylinder>
        </geometry>
        <max_contacts>1</max_contacts>
        <surface>
          <friction>
            <ode>
              <mu>1.0</mu>
              <mu2>1.0</mu2>
              <fdir1>0 0 1</fdir1>
              <slip1>0.0</slip1>
              <slip2>0.0</slip2>
            </ode>
          </friction>
          <contact>
            <ode>
              <min_depth>0.005</min_depth>
              <kp>1e8</kp>
            </ode>
          </contact>
        </surface>
      </collision>
      <visual name="tire_visual">
        <pose>0 0 -0.08 3.14159 1.570796 0</pose>
        <geometry>
          <mesh>
            <uri>model://kart/meshes/front_wheel.obj</uri>
          </mesh>
        </geometry>
      </visual>
    </link>
    <link name="front_right_wheel">
      <pose>0.47 -0.5 0.34697 1.52 0.0 0.0</pose>
      <inertial>
        <mass>12</mass>
        <!-- estimated from http://www.rzrforums.net/wheels-tires/1729-tire-wheel-weights-most-sizes.html -->
        <inertia>
          <ixx>0.5</ixx>
          <ixy>0.0</ixy>
          <iyy>0.5</iyy>
          <ixz>0.0</ixz>
          <iyz>0.0</iyz>
          <izz>1.0</izz>
        </inertia>
      </inertial>
      <collision name="collision">
        <geometry>
          <cylinder>
            <radius>0.127</radius>
            <length>0.1143</length>
          </cylinder>
        </geometry>
        <max_contacts>1</max_contacts>
        <surface>
          <friction>
            <ode>
              <mu>1.0</mu>
              <mu2>1.0</mu2>
              <fdir1>0 0 1</fdir1>
              <slip1>0.0</slip1>
              <slip2>0.0</slip2>
            </ode>
          </friction>
          <contact>
            <ode>
              <min_depth>0.005</min_depth>
              <kp>1e8</kp>
            </ode>
          </contact>
        </surface>
      </collision>
      <visual name="tire_visual">
        <pose>0 0 -0.08 0 -1.570796 0</pose>
        <geometry>
          <mesh>
            <uri>model://kart/meshes/front_wheel.obj</uri>
          </mesh>
        </geometry>
      </visual>
    </link>
    <link name="rear_left_wheel">
      <pose>-0.31 0.5 0.34697 -1.52 0.0 0.0</pose>
      <inertial>
        <mass>12</mass>
        <!-- estimated from http://www.rzrforums.net/wheels-tires/1729-tire-wheel-weights-most-sizes.html -->
        <inertia>
          <ixx>0.5</ixx>
          <ixy>0.0</ixy>
          <iyy>0.5</iyy>
          <ixz>0.0</ixz>
          <iyz>0.0</iyz>
          <izz>1.0</izz>
        </inertia>
      </inertial>
      <collision name="collision">
        <geometry>
          <cylinder>
            <radius>0.127</radius>
            <length>0.1143</length>
          </cylinder>
        </geometry>
        <max_contacts>1</max_contacts>
        <surface>
          <friction>
            <ode>
              <mu>1.0</mu>
              <mu2>1.0</mu2>
              <fdir1>0 0 1</fdir1>
              <slip1>0.0</slip1>
              <slip2>0.0</slip2>
            </ode>
          </friction>
          <contact>
            <ode>
              <min_depth>0.005</min_depth>
              <kp>1e8</kp>
            </ode>
          </contact>
        </surface>
      </collision>
      <visual name="visual">
        <pose>0 0 -0.2 0 0 0</pose>
        <geometry>
          <mesh>
            <uri>model://kart/meshes/rear_wheel.obj</uri>
          </mesh>
        </geometry>
      </visual>
    </link>
    <link name="rear_right_wheel">
      <pose>-0.31 -0.5 0.34697 1.52 0.0 0.0</pose>
      <inertial>
        <mass>12</mass>
        <!-- estimated from http://www.rzrforums.net/wheels-tires/1729-tire-wheel-weights-most-sizes.html -->
        <inertia>
          <ixx>0.5</ixx>
          <ixy>0.0</ixy>
          <iyy>0.5</iyy>
          <ixz>0.0</ixz>
          <iyz>0.0</iyz>
          <izz>1.0</izz>
        </inertia>
      </inertial>
      <collision name="collision">
        <geometry>
          <cylinder>
            <radius>0.127</radius>
            <length>0.1143</length>
          </cylinder>
        </geometry>
        <max_contacts>1</max_contacts>
        <surface>
          <friction>
            <ode>
              <mu>1.0</mu>
              <mu2>1.0</mu2>
              <fdir1>0 0 1</fdir1>
              <slip1>0.0</slip1>
              <slip2>0.0</slip2>
            </ode>
          </friction>
          <contact>
            <ode>
              <min_depth>0.005</min_depth>
              <kp>1e8</kp>
            </ode>
          </contact>
        </surface>
      </collision>
      <visual name="visual">
        <pose>0 0 -0.2 0 0 0</pose>
        <geometry>
          <mesh>
            <uri>model://kart/meshes/rear_wheel.obj</uri>
          </mesh>
        </geometry>
      </visual>
    </link>
    <link name="front_right_wheel_steering_block">
      <pose>0.47 -0.5 0.35515 1.570796 0.0 0.0</pose>
      <inertial>
        <mass>1</mass>
        <inertia>
          <ixx>0.01</ixx>
          <ixy>0.0</ixy>
          <iyy>0.01</iyy>
          <ixz>0.0</ixz>
          <iyz>0.0</iyz>
          <izz>0.01</izz>
        </inertia>
      </inertial>
      <collision name="collision">
        <geometry>
          <cylinder>
            <radius>0.05</radius>
            <length>0.01</length>
          </cylinder>
        </geometry>
      </collision>
    </link>
    <link name="front_left_wheel_steering_block">
      <pose>0.47 0.5 0.35515 1.570796 0.0 0.0</pose>
      <inertial>
        <mass>1</mass>
        <inertia>
          <ixx>0.01</ixx>
          <ixy>0.0</ixy>
          <iyy>0.01</iyy>
          <ixz>0.0</ixz>
          <iyz>0.0</iyz>
          <izz>0.01</izz>
        </inertia>
      </inertial>
      <collision name="collision">
        <geometry>
          <cylinder>
            <radius>0.05</radius>
            <length>0.01</length>
          </cylinder>
        </geometry>
      </collision>
    </link>
    <joint type="revolute" name="front_left_steering_joint">
      <child>front_left_wheel_steering_block</child>
      <parent>base_link</parent>
      <axis>
        <xyz>0 0 1</xyz>
        <limit>
          <lower>-0.7727</lower>
          <upper>0.7727</upper>
        </limit>
        <dynamics>
          <damping>50.0</damping>
        </dynamics>
        <use_parent_model_frame>true</use_parent_model_frame>
      </axis>
      <physics>
        <ode>
          <cfm_damping>1</cfm_damping>
          <limit>
            <cfm>0.000000</cfm>
            <erp>0.900000</erp>
          </limit>
        </ode>
      </physics>
    </joint>
    <joint type="revolute" name="front_left_wheel_joint">
      <child>front_left_wheel</child>
      <parent>front_left_wheel_steering_block</parent>
      <axis>
        <xyz>0 1 0.05</xyz>
        <use_parent_model_frame>true</use_parent_model_frame>
      </axis>
    </joint>
    <joint type="revolute" name="front_right_steering_joint">
      <child>front_right_wheel_steering_block</child>
      <parent>base_link</parent>
      <axis>
        <xyz>0 0 1</xyz>
        <limit>
          <lower>-0.7727</lower>
          <upper>0.7727</upper>
        </limit>
        <dynamics>
          <damping>50.0</damping>
        </dynamics>
        <use_parent_model_frame>true</use_parent_model_frame>
      </axis>
      <physics>
        <ode>
          <cfm_damping>1</cfm_damping>
          <limit>
            <cfm>0.000000</cfm>
            <erp>0.900000</erp>
          </limit>
        </ode>
      </physics>
    </joint>
    <joint type="revolute" name="front_right_wheel_joint">
      <child>front_right_wheel</child>
      <parent>front_right_wheel_steering_block</parent>
      <axis>
        <xyz>0 1 -0.05</xyz>
        <use_parent_model_frame>true</use_parent_model_frame>
      </axis>
    </joint>
    <joint type="revolute" name="rear_left_wheel_joint">
      <child>rear_left_wheel</child>
      <parent>base_link</parent>
      <axis>
        <xyz>0 1 0.05</xyz>
        <use_parent_model_frame>true</use_parent_model_frame>
      </axis>
    </joint>
    <joint type="revolute" name="rear_right_wheel_joint">
      <pose>0.0 0.0 -0.1 0 0 0</pose>
      <child>rear_right_wheel</child>
      <parent>base_link</parent>
      <axis>
        <xyz>0 1 -0.05</xyz>
        <use_parent_model_frame>true</use_parent_model_frame>
      </axis>
    </joint>
<!--     <joint type="revolute" name="rear_differential_joint">
      <child>rear_right_wheel</child>
      <parent>rear_left_wheel</parent>
      <axis>
        <xyz>0 1 0</xyz>
        <dynamics>
          <damping>70</damping>
        </dynamics>
        <use_parent_model_frame>true</use_parent_model_frame>
      </axis>
      <physics>
        <ode>
          <erp>0</erp>
          <cfm>1000</cfm>
          <cfm_damping>1</cfm_damping>
        </ode>
      </physics>
    </joint> -->
    <include>
      <uri>model://gps</uri>
      <pose>0 0 0 0 0 0</pose>
      <name>gps</name>
    </include>
    <joint name='gps_joint' type='fixed'>
      <child>gps::link</child>
      <parent>base_link</parent>
    </joint>
    <plugin name='barometer_plugin' filename='libgazebo_barometer_plugin.so'>
      <robotNamespace/>
      <pubRate>10</pubRate>
      <baroTopic>/baro</baroTopic>
    </plugin>
    <plugin name='groundtruth_plugin' filename='libgazebo_groundtruth_plugin.so'>
      <robotNamespace/>
    </plugin>
    <plugin name='magnetometer_plugin' filename='libgazebo_magnetometer_plugin.so'>
      <robotNamespace/>
      <pubRate>100</pubRate>
      <noiseDensity>0.0004</noiseDensity>
      <randomWalk>6.4e-06</randomWalk>
      <biasCorrelationTime>600</biasCorrelationTime>
      <magTopic>/mag</magTopic>
    </plugin>
    <plugin name='mavlink_interface' filename='libgazebo_mavlink_interface.so'>
      <robotNamespace/>
      <imuSubTopic>/imu</imuSubTopic>
      <magSubTopic>/mag</magSubTopic>
      <baroSubTopic>/baro</baroSubTopic>
      <gpsSubTopic>/gps</gpsSubTopic>
      <mavlink_addr>INADDR_ANY</mavlink_addr>
      <mavlink_tcp_port>4560</mavlink_tcp_port>
      <mavlink_udp_port>14560</mavlink_udp_port>
      <serialEnabled>0</serialEnabled>
      <serialDevice>/dev/ttyACM0</serialDevice>
      <baudRate>921600</baudRate>
      <qgc_addr>INADDR_ANY</qgc_addr>
      <qgc_udp_port>14550</qgc_udp_port>
      <sdk_addr>INADDR_ANY</sdk_addr>
      <sdk_udp_port>14540</sdk_udp_port>
      <hil_mode>0</hil_mode>
      <hil_state_level>0</hil_state_level>
      <send_vision_estimation>0</send_vision_estimation>
      <send_odometry>1</send_odometry>
      <enable_lockstep>1</enable_lockstep>
      <use_tcp>1</use_tcp>
      <motorSpeedCommandPubTopic>/gazebo/command/motor_speed</motorSpeedCommandPubTopic>
      <control_channels>
        <!--
        <channel name="front_left_wheel_drive">
          <input_index>3</input_index>
          <input_offset>0</input_offset>
          <input_scaling>10</input_scaling>
          <zero_position_disarmed>0</zero_position_disarmed>
          <zero_position_armed>0</zero_position_armed>
          <joint_control_type>velocity_kinematic</joint_control_type>
          <joint_name>front_left_wheel_joint</joint_name>
        </channel>
        <channel name="front_right_wheel_drive">
          <input_index>4</input_index>
          <input_offset>0</input_offset>
          <input_scaling>10</input_scaling>
          <zero_position_disarmed>0</zero_position_disarmed>
          <zero_position_armed>0</zero_position_armed>
          <joint_control_type>velocity_kinematic</joint_control_type>
          <joint_name>front_right_wheel_joint</joint_name>
        </channel>
      -->
        <channel name="rear_left_wheel_drive">
          <input_index>5</input_index>
          <input_offset>0</input_offset>
          <input_scaling>40</input_scaling>
          <zero_position_disarmed>0</zero_position_disarmed>
          <zero_position_armed>0</zero_position_armed>
          <joint_control_type>velocity</joint_control_type>
          <joint_name>rear_left_wheel_joint</joint_name>
          <joint_control_pid>
            <p>50</p>
            <i>20</i>
            <d>2</d>
            <iMax>800</iMax>
            <iMin>-800</iMin>
            <cmdMax>1200</cmdMax>
            <cmdMin>-1200</cmdMin>
          </joint_control_pid>
        </channel>
        <channel name="rear_right_wheel_drive">
          <input_index>6</input_index>
          <input_offset>0</input_offset>
          <input_scaling>40</input_scaling>
          <zero_position_disarmed>0</zero_position_disarmed>
          <zero_position_armed>0</zero_position_armed>
          <joint_control_type>velocity</joint_control_type>
          <joint_name>rear_right_wheel_joint</joint_name>
          <joint_control_pid>
            <p>50</p>
            <i>20</i>
            <d>2</d>
            <iMax>800</iMax>
            <iMin>-800</iMin>
            <cmdMax>1200</cmdMax>
            <cmdMin>-1200</cmdMin>
          </joint_control_pid>
        </channel>
        <channel name="left_wheel_steering">
          <input_index>0</input_index>
          <input_offset>0</input_offset>
          <input_scaling>-0.9</input_scaling>
          <zero_position_disarmed>0</zero_position_disarmed>
          <zero_position_armed>0</zero_position_armed>
          <joint_control_type>position</joint_control_type>
          <joint_name>front_left_steering_joint</joint_name>
          <joint_control_pid>
            <p>80</p>
            <i>40</i>
            <d>0.1</d>
            <iMax>40</iMax>
            <iMin>-40</iMin>
            <cmdMax>80</cmdMax>
            <cmdMin>-80</cmdMin>
          </joint_control_pid>
        </channel>
        <channel name="right_wheel_steering">
          <input_index>1</input_index>
          <input_offset>0</input_offset>
          <input_scaling>-0.9</input_scaling>
          <zero_position_disarmed>0</zero_position_disarmed>
          <zero_position_armed>0</zero_position_armed>
          <joint_control_type>position</joint_control_type>
          <joint_name>front_right_steering_joint</joint_name>
          <joint_control_pid>
            <p>80</p>
            <i>40</i>
            <d>0.1</d>
            <iMax>40</iMax>
            <iMin>-40</iMin>
            <cmdMax>80</cmdMax>
            <cmdMin>-80</cmdMin>
          </joint_control_pid>
        </channel>
      </control_channels>
    </plugin>
    <plugin name='gazebo_imu_plugin' filename='libgazebo_imu_plugin.so'>
      <robotNamespace></robotNamespace>
      <linkName>rover/imu_link</linkName>
      <imuTopic>/imu</imuTopic>
      <gyroscopeNoiseDensity>0.0003394</gyroscopeNoiseDensity>
      <gyroscopeRandomWalk>3.8785e-05</gyroscopeRandomWalk>
      <gyroscopeBiasCorrelationTime>1000.0</gyroscopeBiasCorrelationTime>
      <gyroscopeTurnOnBiasSigma>0.0087</gyroscopeTurnOnBiasSigma>
      <accelerometerNoiseDensity>0.004</accelerometerNoiseDensity>
      <accelerometerRandomWalk>0.006</accelerometerRandomWalk>
      <accelerometerBiasCorrelationTime>300.0</accelerometerBiasCorrelationTime>
      <accelerometerTurnOnBiasSigma>0.196</accelerometerTurnOnBiasSigma>
    </plugin>
  </model>
</sdf>
